Workbook

Sheet ACTIVITÉS
A1: NUMERO ACTIVITE | B1: RESPONSABLE FACTURATION | C1: NOM DE L'ACTIVITÉ | D1: DATE DÉBUT | E1: DATE FIN | F1: Nbre jour occupation (formule) | G1: Client interne ou externe | H1: CATÉGORIE (Rébecca) | I1: SALLE (menu déroulant) | J1: TEMPS RÉMI (en heure) | K1: DÉPARTEMENT (menu déroulant À VENIR) | L1: PRIX SALLE SANS FRAIS (formule) interne seulement | M1: NUMÉRO DE FACTURE, RÉQUISITION INTERNE OU ENCAISSEMENT | N1: 892-9020-00-849 SCOLAIRE | O1: 892-9020-01-849 SCOLAIRE | P1: 892-9020-04-849 SCOLAIRE | Q1: 892-9020-00-851 892-9020-01-851 892-9020-04-851 GOUV QC | R1: 892-9020-00-853 892-9020-01-853 892-9020-04-853 MUNICIPAL | S1: 892-9020-00-864 BAR SFB | T1: 892-9020-01-864 BAR POLY | U1: 892-9020-00-869 892-9020-01-869 VESTIAIRE | V1: 892-9020-00-870 CIE EXTERNE (SFB, DT, HOTES) | W1: 892-9020-01-870 CIE EXTERNE (POLY, DT, HOTES) | X1: 892-9020-04-870 CIE EXTERNE (AGENT) | Y1: 892-9020-05-870 CIE EXTERNE (PROJO CINÉ-CLUB) | Z1: 892-9020-06-870 CIE EXTERNE (PROJO SFB) | AA1: 892-9020-07-870 CIE EXTERNE (PROJO POLY) | AB1: 892-9020-00-889 INTERNE (SFB, HOTES) | AC1: 892-9020-01-889 INTERNE (POLY, HOTES) | AD1: 892-9020-04-889 INTERNE (AGENT) | AE1: 892-9020-05-889 INTERNE (PROJO CINÉ-CLUB) | AF1: 892-9020-06-889 INTERNE (PROJO SFB) | AG1: 892-9020-07-889 INTERNE (PROJO POLY) | AH1: REVENUS TOTAL RÉÈL
A2: SFB 2627-001 | F2: 1 | L2: 0 | AH2: =SUM(Q2:AG2) -> 0
A3: SFB 2627-002 | F3: =E3-D3+1 -> 1 | AH3: =SUM(Q3:AG3) -> 0
A4: SFB 2627-003 | F4: =E4-D4+1 -> 1 | AH4: =SUM(Q4:AG4) -> 0
A5: SFB 2627-004 | F5: =E5-D5+1 -> 1 | AH5: =SUM(Q5:AG5) -> 0
A6: SFB 2627-005 | F6: =E6-D6+1 -> 1 | AH6: =SUM(Q6:AG6) -> 0
A7: SFB 2627-006 | F7: =E7-D7+1 -> 1 | AH7: =SUM(Q7:AG7) -> 0
A8: SFB 2627-007 | F8: =E8-D8+1 -> 1 | AH8: =SUM(Q8:AG8) -> 0
A9: SFB 2627-008 | F9: =E9-D9+1 -> 1 | AH9: =SUM(Q9:AG9) -> 0
A10: SFB 2627-009 | F10: =E10-D10+1 -> 1 | AH10: =SUM(Q10:AG10) -> 0
A11: SFB 2627-010 | F11: =E11-D11+1 -> 1 | AH11: =SUM(Q11:AG11) -> 0
A12: SFB 2627-011 | F12: =E12-D12+1 -> 1 | AH12: =SUM(Q12:AG12) -> 0
A13: SFB 2627-012 | F13: =E13-D13+1 -> 1 | AH13: =SUM(Q13:AG13) -> 0
A14: SFB 2627-013 | F14: =E14-D14+1 -> 1 | AH14: =SUM(Q14:AG14) -> 0
... A32: SFB 2627-031 | F32: =E32-D32+1 -> 1 | AH32: =SUM(Q32:AG32) -> 0
C33: TOTAUX AU 30 SEPTEMBRE 2026
F34: =E34-D34+1 -> 1
F35: =E35-D35+1 -> 1
F36: =E36-D36+1 -> 1
F37: =E37-D37+1 -> 1
F38: =E38-D38+1 -> 1
F39: =E39-D39+1 -> 1
F40: =E40-D40+1 -> 1
F41: =E41-D41+1 -> 1
F42: =E42-D42+1 -> 1
F43: =E43-D43+1 -> 1
F44: =E44-D44+1 -> 1
C45: TOTAUX AU 31 DÉCEMBRE 2026
F46: =E46-D46+1 -> 1
F47: =E47-D47+1 -> 1
F48: =E48-D48+1 -> 1
F49: =E49-D49+1 -> 1
F50: =E50-D50+1 -> 1
F51: =E51-D51+1 -> 1
F52: =E52-D52+1 -> 1
F53: =E53-D53+1 -> 1
C54: TOTAUX AU 31 MARS 2027
F55: =E55-D55+1 -> 1
F56: =E56-D56+1 -> 1
F57: =E57-D57+1 -> 1
...

Sheet Interne-Externe
A1: Clients
A2: interne
A3: externe

Sheet SOMMAIRE PAR DÉPARTEMENTS
A1: DÉPARTEMENTS | B1: MONTANT
A2: ACEECJ | B2: =SUMIFS(ACTIVITÉS!L:L,ACTIVITÉS!K:K,'SOMMAIRE PAR DÉPARTEMENTS'!A2) -> 0
A3: ANIMATION PÉDAGOGIQUE (ALEXANDRA HÉBERT) | B3: =SUMIFS(ACTIVITÉS!L:L,ACTIVITÉS!K:K,'SOMMAIRE PAR DÉPARTEMENTS'!A3) -> 0
A4: BICQ | B4: =SUMIFS(ACTIVITÉS!L:L,ACTIVITÉS!K:K,'SOMMAIRE PAR DÉPARTEMENTS'!A4) -> 0
A5: COMMUNICATION | B5: =SUMIFS(ACTIVITÉS!L:L,ACTIVITÉS!K:K,'SOMMAIRE PAR DÉPARTEMENTS'!A5) -> 0
A6: DIRECTION DES ÉTUDES (ENSEIGNANTS) | B6: =SUMIFS(ACTIVITÉS!L:L,ACTIVITÉS!K:K,'SOMMAIRE PAR DÉPARTEMENTS'!A6) -> 0
A7: DIRECTION GÉNÉRALE | B7: =SUMIFS(ACTIVITÉS!L:L,ACTIVITÉS!K:K,'SOMMAIRE PAR DÉPARTEMENTS'!A7) -> 0
A8: DSATC | B8: =SUMIFS(ACTIVITÉS!L:L,ACTIVITÉS!K:K,'SOMMAIRE PAR DÉPARTEMENTS'!A8) -> 0
A9: FONDATION ASSELIN | B9: =SUMIFS(ACTIVITÉS!L:L,ACTIVITÉS!K:K,'SOMMAIRE PAR DÉPARTEMENTS'!A9) -> 0
A10: VIE ÉTUDIANTE (SOPHIE HUPPÉ) | B10: =SUMIFS(ACTIVITÉS!L:L,ACTIVITÉS!K:K,'SOMMAIRE PAR DÉPARTEMENTS'!A10) -> 0
A11: BRI - BUREAU DE LA RECHERCHE ET DE L'INNOVATION | B11: =SUMIFS(ACTIVITÉS!L:L,ACTIVITÉS!K:K,'SOMMAIRE PAR DÉPARTEMENTS'!A11) -> 0
A12: CLIENT EXTERNE | B12: =SUMIFS(ACTIVITÉS!L:L,ACTIVITÉS!K:K,'SOMMAIRE PAR DÉPARTEMENTS'!A12) -> 0
A13: DRH - DIRECTION DES RESSOURCES HUMAINES | B13: =SUMIFS(ACTIVITÉS!L:L,ACTIVITÉS!K:K,'SOMMAIRE PAR DÉPARTEMENTS'!A13) -> 0
... A15: DIRECTION DES SERVICES INFORMATIONNELLES | B15: =SUMIFS(ACTIVITÉS!L:L,ACTIVITÉS!K:K,'SOMMAIRE PAR DÉPARTEMENTS'!A15) -> 0
K415: BR

Sheet SALLES
A1: SALLE | B1: PRIX INTERNE | C1: PRIX EXTERNE | G1: NE PAS MODIFIER LES NOMS DES SALLES, CAR ÇA NE CHANGERA PAS AUTOMATIQUEMENT
A2: POLY | B2: 175
A3: SALON | B3: 50 | C3: 100
A4: SFB-SALON-HALL | B4: 200
A5: SFB-POLY | B5: =200+175 -> 375
A6: HALL SFB | B6: 0

Sheet Catégorie
A1: Bleu
A2: Vert
A3: Jaune

Sheet Notes
A1: SFB sans frais | B1: 200$ par jour
A2: SALON SFB sans frais | B2: 50$/jour
A3: POLY sans frais | B3: 175$ par jour
A5: DIRECTION DES ÉTUDES | B5: enseignants
A6: DEVE | B6: vie étudiante qui relève de Sophie Huppé
